Workbook

Sheet Leia-me
A1: Título | B1: Sintomas organizacionais do GT Evoluir Modelo de Negócio SUSEP Vida e RE (Seguros Unimed)
A2: Base | B2: Notebook 'Estratégia e Operações Susep: Gestão de Vida e Ramos Elementares' (NotebookLM, id ede3f19c-4ce2-4ccf-a50c-ddcfd4d96e95): 24 fontes (1 deck do PIE mai/26 e 23 atas de reuniões do GT, mentores e consultoria, de 30/03/2026 a 17/08/2026). Ver aba Fontes.
A3: Data de elaboração | B3: 01/09/2026
A4: O que é sintoma aqui | B4: Problema, bloqueio, atrito ou limitação registrado nas fontes como algo que dificulta o trabalho do grupo ou o resultado do negócio. Não inclui iniciativas, entregas ou decisões em si, só o que elas revelam de problema.
A5: Categorias e elementos | B5: Seis categorias definidas pelo solicitante (Organização do Trabalho, Governança, Coordenação, Informação, Recursos, Tecnologia), com os elementos listados na aba Taxonomia. 'Data fixação' foi interpretado como Dataficação (transformação de atividade em dado).
A6: Perguntas-guia | B6: Cada sintoma responde às três perguntas na aba Sintomas: (1) Como este elemento se manifesta na prática; (2) Quais relações estruturais o sustentam; (3) Que evidências permitem avaliá-lo. A coluna 'Evidência nas fontes' traz citação ou paráfrase fiel com o código da fonte. Atenção: as colunas 'Como se manifesta' e 'Evidência nas fontes' descrevem o que as fontes registram; as colunas 'Relações estruturais' e 'Evidências para avaliá-lo' são leitura analítica deste diagnóstico (inferência e proposta de medição), não citação.
A7: Tipo de evidência | B7: Direta: o sintoma está dito nas fontes com essas palavras ou equivalentes. Inferida: o sintoma é lido a partir de fatos registrados, mas a fonte não o nomeia. Sem evidência: elemento da taxonomia sem registro nas 24 fontes.
A8: Classificação | B8: Cada sintoma recebeu uma categoria e um elemento principais. Vários poderiam entrar em mais de um (ex.: renovação as-is é Autonomia, Handoff e Ferramenta). A escolha privilegiou a causa mais próxima descrita na própria fonte.
A9: Recorrência | B9: 'Nº de fontes' é calculado por fórmula a partir da coluna Fontes. 'Primeira' e 'Última menção' mostram a persistência do sintoma no período.
A10: Limites | B10: As fontes são atas produzidas pelo próprio grupo; registram o que foi dito em reunião, não medições. Algumas trazem marcas de geração automática (nota de sistema em F14, pergunta de assistente ao final de F22). O deck do PIE foi lido a partir das imagens dos slides. F07 e F08 são a mesma ata; F24 traz o mesmo bloco duplicado. Nenhum número foi criado além do que está nas fontes.
A11: Como usar | B11: Filtre a aba Sintomas por Categoria ou Elemento. A aba Resumo conta sintomas por categoria e a aba Taxonomia mostra cobertura por elemento, apontando lacunas ('Sem evidência nas fontes').
A12: Guias (lente de design organizacional) | B12: Guia 1 Lente DO: o que é disfuncional e o que precisa ser definido, por dimensão do design. Guia 2 Fluxo demanda: como os desafios chegam e saem, critérios de relevância e modelo de pontuação. Guia 3 Triagem: tipos de problema (estrutural, BAU, adequação, oportunidade), time de análise, o que estudar ou terceirizar, controle e medida. Guia 4 Concepção-Entrega: pipeline da estratégia à entrega com gates e regras. Guia 5 Blueprint Org: governança, times, dinâmicas e fluxo em raias. Guia 6 Co-criação: sessões para criar com o time e indicadores do design.
A13: Status dos guias | B13: PROPOSTA. Os guias não são fatos das fontes: são um desenho derivado dos sintomas, para ser validado e ajustado pelo próprio time (Guia 6). Células amarelas = proposta; azuis = entrada a preencher; cada linha cita os IDs dos sintomas que endereça. Números dentro das propostas (cotas, limites, horas de dedicação, pesos) são pontos de partida para calibrar nas sessões do Guia 6, não recomendações fechadas.

Sheet Resumo
A1: Categoria | B1: Nº de sintomas | C1: % do total | D1: Evidência direta | E1: Evidência inferida
A2: Organização do Trabalho | B2: =COUNTIF(Sintomas!$B$2:$B$73,A2) -> 16 | C2: =IF($B$8=0,0,B2/$B$8) -> 0.22222222 | D2: =COUNTIFS(Sintomas!$B$2:$B$73,A2,Sintomas!$N$2:$N$73,"Direta") -> 15 | E2: =COUNTIFS(Sintomas!$B$2:$B$73,A2,Sintomas!$N$2:$N$73,"Inferida") -> 1
A3: Governança | B3: =COUNTIF(Sintomas!$B$2:$B$73,A3) -> 10 | C3: =IF($B$8=0,0,B3/$B$8) -> 0.13888889 | D3: =COUNTIFS(Sintomas!$B$2:$B$73,A3,Sintomas!$N$2:$N$73,"Direta") -> 9 | E3: =COUNTIFS(Sintomas!$B$2:$B$73,A3,Sintomas!$N$2:$N$73,"Inferida") -> 1
A4: Coordenação | B4: =COUNTIF(Sintomas!$B$2:$B$73,A4) -> 10 | C4: =IF($B$8=0,0,B4/$B$8) -> 0.13888889 | D4: =COUNTIFS(Sintomas!$B$2:$B$73,A4,Sintomas!$N$2:$N$73,"Direta") -> 10 | E4: =COUNTIFS(Sintomas!$B$2:$B$73,A4,Sintomas!$N$2:$N$73,"Inferida") -> 0
A5: Informação | B5: =COUNTIF(Sintomas!$B$2:$B$73,A5) -> 16 | C5: =IF($B$8=0,0,B5/$B$8) -> 0.22222222 | D5: =COUNTIFS(Sintomas!$B$2:$B$73,A5,Sintomas!$N$2:$N$73,"Direta") -> 16 | E5: =COUNTIFS(Sintomas!$B$2:$B$73,A5,Sintomas!$N$2:$N$73,"Inferida") -> 0
A6: Recursos | B6: =COUNTIF(Sintomas!$B$2:$B$73,A6) -> 9 | C6: =IF($B$8=0,0,B6/$B$8) -> 0.125 | D6: =COUNTIFS(Sintomas!$B$2:$B$73,A6,Sintomas!$N$2:$N$73,"Direta") -> 9 | E6: =COUNTIFS(Sintomas!$B$2:$B$73,A6,Sintomas!$N$2:$N$73,"Inferida") -> 0
A7: Tecnologia | B7: =COUNTIF(Sintomas!$B$2:$B$73,A7) -> 11 | C7: =IF($B$8=0,0,B7/$B$8) -> 0.15277778 | D7: =COUNTIFS(Sintomas!$B$2:$B$73,A7,Sintomas!$N$2:$N$73,"Direta") -> 10 | E7: =COUNTIFS(Sintomas!$B$2:$B$73,A7,Sintomas!$N$2:$N$73,"Inferida") -> 0
A8: Total | B8: =SUM(B2:B7) -> 72 | C8: =SUM(C2:C7) -> 1 | D8: =SUM(D2:D7) -> 69 | E8: =SUM(E2:E7) -> 2
A10: Sintomas mais recorrentes (por nº de fontes)
A11: ID | B11: Nº de fontes | C11: Categoria | D11: Sintoma
A12: =INDEX(Sintomas!$A$2:$A$73,MATCH(LARGE(Sintomas!$O$2:$O$73,1),Sintomas!$O$2:$O$73,0)) -> RE-04 | B12: =INDEX(Sintomas!$J$2:$J$73,MATCH(LARGE(Sintomas!$O$2:$O$73,1),Sintomas!$O$2:$O$73,0)) -> 9 | C12: =INDEX(Sintomas!$B$2:$B$73,MATCH(LARGE(Sintomas!$O$2:$O$73,1),Sintomas!$O$2:$O$73,0)) -> Recursos | D12: =INDEX(Sintomas!$D$2:$D$73,MATCH(LARGE(Sintomas!$O$2:$O$73,1),Sintomas!$O$2:$O$73,0)) -> Conflitos de agenda crônicos: falta de quórum, fóruns adiados, temas espremidos
A13: =INDEX(Sintomas!$A$2:$A$73,MATCH(LARGE(Sintomas!$O$2:$O$73,2),Sintomas!$O$2:$O$73,0)) -> OT-11 | B13: =INDEX(Sintomas!$J$2:$J$73,MATCH(LARGE(Sintomas!$O$2:$O$73,2),Sintomas!$O$2:$O$73,0)) -> 7 | C13: =INDEX(Sintomas!$B$2:$B$73,MATCH(LARGE(Sintomas!$O$2:$O$73,2),Sintomas!$O$2:$O$73,0)) -> Organização do Trabalho | D13: =INDEX(Sintomas!$D$2:$D$73,MATCH(LARGE(Sintomas!$O$2:$O$73,2),Sintomas!$O$2:$O$73,0)) -> Vida e RE misturados no mesmo grupo, relatório e metas, gerando confusão estratégica
A14: =INDEX(Sintomas!$A$2:$A$73,MATCH(LARGE(Sintomas!$O$2:$O$73,3),Sintomas!$O$2:$O$73,0)) -> GV-10 | B14: =INDEX(Sintomas!$J$2:$J$73,MATCH(LARGE(Sintomas!$O$2:$O$73,3),Sintomas!$O$2:$O$73,0)) -> 7 | C14: =INDEX(Sintomas!$B$2:$B$73,MATCH(LARGE(Sintomas!$O$2:$O$73,3),Sintomas!$O$2:$O$73,0)) -> Governança | D14: =INDEX(Sintomas!$D$2:$D$73,MATCH(LARGE(Sintomas!$O$2:$O$73,3),Sintomas!$O$2:$O$73,0)) -> Ritos de revisão com mentores comprimidos, adiados ou ausentes
A15: =INDEX(Sintomas!$A$2:$A$73,MATCH(LARGE(Sintomas!$O$2:$O$73,4),Sintomas!$O$2:$O$73,0)) -> OT-16 | B15: =INDEX(Sintomas!$J$2:$J$73,MATCH(LARGE(Sintomas!$O$2:$O$73,4),Sintomas!$O$2:$O$73,0)) -> 6 | C15: =INDEX(Sintomas!$B$2:$B$73,MATCH(LARGE(Sintomas!$O$2:$O$73,4),Sintomas!$O$2:$O$73,0)) -> Organização do Trabalho | D15: =INDEX(Sintomas!$D$2:$D$73,MATCH(LARGE(Sintomas!$O$2:$O$73,4),Sintomas!$O$2:$O$73,0)) -> Engajamento só durante a reunião; sem avanço entre agendas e 'lições de casa' não feitas
A16: =INDEX(Sintomas!$A$2:$A$73,MATCH(LARGE(Sintomas!$O$2:$O$73,5),Sintomas!$O$2:$O$73,0)) -> GV-05 | B16: =INDEX(Sintomas!$J$2:$J$73,MATCH(LARGE(Sintomas!$O$2:$O$73,5),Sintomas!$O$2:$O$73,0)) -> 6 | C16: =INDEX(Sintomas!$B$2:$B$73,MATCH(LARGE(Sintomas!$O$2:$O$73,5),Sintomas!$O$2:$O$73,0)) -> Governança | D16: =INDEX(Sintomas!$D$2:$D$73,MATCH(LARGE(Sintomas!$O$2:$O$73,5),Sintomas!$O$2:$O$73,0)) -> Meta de 20% sem base rastreável e divergente do orçamento da Controladoria
A17: =INDEX(Sintomas!$A$2:$A$73,MATCH(LARGE(Sintomas!$O$2:$O$73,6),Sintomas!$O$2:$O$73,0)) -> GV-06 | B17: =INDEX(Sintomas!$J$2:$J$73,MATCH(LARGE(Sintomas!$O$2:$O$73,6),Sintomas!$O$2:$O$73,0)) -> 5 | C17: =INDEX(Sintomas!$B$2:$B$73,MATCH(LARGE(Sintomas!$O$2:$O$73,6),Sintomas!$O$2:$O$73,0)) -> Governança | D17: =INDEX(Sintomas!$D$2:$D$73,MATCH(LARGE(Sintomas!$O$2:$O$73,6),Sintomas!$O$2:$O$73,0)) -> Priorização difusa: 'focar em tudo resulta em não entregar nada'; comitê de priorização ainda como MVP
A18: =INDEX(Sintomas!$A$2:$A$73,MATCH(LARGE(Sintomas!$O$2:$O$73,7),Sintomas!$O$2:$O$73,0)) -> GV-09 | B18: =INDEX(Sintomas!$J$2:$J$73,MATCH(LARGE(Sintomas!$O$2:$O$73,7),Sintomas!$O$2:$O$73,0)) -> 5 | C18: =INDEX(Sintomas!$B$2:$B$73,MATCH(LARGE(Sintomas!$O$2:$O$73,7),Sintomas!$O$2:$O$73,0)) -> Governança | D18: =INDEX(Sintomas!$D$2:$D$73,MATCH(LARGE(Sintomas!$O$2:$O$73,7),Sintomas!$O$2:$O$73,0)) -> Ferramenta de gestão trocada duas vezes em seis meses (Jira para Stratws em jan/26, Stratws para Jira em jun/26), zerando histórico
A19: =INDEX(Sintomas!$A$2:$A$73,MATCH(LARGE(Sintomas!$O$2:$O$73,8),Sintomas!$O$2:$O$73,0)) -> IN-14 | B19: =INDEX(Sintomas!$J$2:$J$73,MATCH(LARGE(Sintomas!$O$2:$O$73,8),Sintomas!$O$2:$O$73,0)) -> 5 | C19: =INDEX(Sintomas!$B$2:$B$73,MATCH(LARGE(Sintomas!$O$2:$O$73,8),Sintomas!$O$2:$O$73,0)) -> Informação | D19: =INDEX(Sintomas!$D$2:$D$73,MATCH(LARGE(Sintomas!$O$2:$O$73,8),Sintomas!$O$2:$O$73,0)) -> Concorrência agressiva percebida tarde; radar de mercado ainda em construção
A20: =INDEX(Sintomas!$A$2:$A$73,MATCH(LARGE(Sintomas!$O$2:$O$73,9),Sintomas!$O$2:$O$73,0)) -> TE-08 | B20: =INDEX(Sintomas!$J$2:$J$73,MATCH(LARGE(Sintomas!$O$2:$O$73,9),Sintomas!$O$2:$O$73,0)) -> 5 | C20: =INDEX(Sintomas!$B$2:$B$73,MATCH(LARGE(Sintomas!$O$2:$O$73,9),Sintomas!$O$2:$O$73,0)) -> Tecnologia | D20: =INDEX(Sintomas!$D$2:$D$73,MATCH(LARGE(Sintomas!$O$2:$O$73,9),Sintomas!$O$2:$O$73,0)) -> Falta de APIs e hub de integração para balcões, cooperativas e multicálculos
A21: =INDEX(Sintomas!$A$2:$A$73,MATCH(LARGE(Sintomas!$O$2:$O$73,10),Sintomas!$O$2:$O$73,0)) -> OT-02 | B21: =INDEX(Sintomas!$J$2:$J$73,MATCH(LARGE(Sintomas!$O$2:$O$73,10),Sintomas!$O$2:$O$73,0)) -> 4 | C21: =INDEX(Sintomas!$B$2:$B$73,MATCH(LARGE(Sintomas!$O$2:$O$73,10),Sintomas!$O$2:$O$73,0)) -> Organização do Trabalho | D21: =INDEX(Sintomas!$D$2:$D$73,MATCH(LARGE(Sintomas!$O$2:$O$73,10),Sintomas!$O$2:$O$73,0)) -> Regras de aceitação médica e subscrição descoladas do mercado geram perda de negócios
A23: Nota: em empate no nº de fontes, a ordem segue a posição na aba Sintomas (chave de ordenação na coluna O).

Sheet Sintomas
A1: ID | B1: Categoria | C1: Elemento | D1: Sintoma / Problema | E1: Como este elemento se manifesta na prática | F1: Quais relações estruturais o sustentam | G1: Que evidências permitem avaliá-lo (indicadores e checagens) | H1: Evidência nas fontes (citação ou paráfrase) | I1: Fontes | J1: Nº de fontes | K1: Primeira menção | L1: Última menção | M1: Ramo / Canal afetado | N1: Tipo de evidência | O1: Chave de ordenação (fórmula)
A2: OT-01 | B2: Organização do Trabalho | C2: Padrões | D2: Reuniões sem pauta prévia e queda de engajamento no formato híbrido | E2: Diversas reuniões na empresa ocorrem sem pauta. Encontros híbridos perdem envolvimento em comparação ao presencial (treinamento OKR). Frente de Cultura lança campanha de boas práticas (pauta, objetivo, resultados esperados). | F2: Ausência de padrão corporativo para convites de reunião; regime híbrido (sextas em home office; cursos às terças e quintas à tarde); cultura de reunião como espaço de descoberta e não de decisão. | G2: % de convites com pauta e resultado esperado; nº de reuniões canceladas ou sem quórum; comparação de participação presencial vs. híbrida; adoção das diretrizes da frente de Cultura. | H2: F21: 'ocorrência frequente de reuniões sem pauta na empresa'; 'queda de engajamento em reuniões no formato híbrido'; 'a interação presencial gerou um grande envolvimento que costuma se perder em reuniões híbridas'. F02: 'risco de possível perda em agendas híbridas'. | I2: F02; F21 | J2: =LEN(I2)-LEN(SUBSTITUTE(I2,"F","")) -> 2 | K2: 30/03/2026 | L2: 03/08/2026 | M2: Vida e RE | N2: Direta | O2: =J2+(1000-ROW())/100000 -> 2.00998
A3: OT-02 | B3: Organização do Trabalho | C3: Padrões | D3: Regras de aceitação médica e subscrição descoladas do mercado geram perda de negócios | E3: Companhia recusa ou manda para exame patologias que o mercado aceita (hipertensão controlada, diabetes, IMC). Corretor orienta o mercado a 'nem calcular na Unimed'. Preço é competitivo; o gargalo real é aceitação e travas sistêmicas. 22% das pendências ligadas a aceitação médica e documentos não devolvidos. Ajustes chegam em ondas (IMC jan/26; tábua e IMC 25 para 30 em ago/26). | F3: Apetite de risco corporativo conservador; auditoria médica com regras fixas; DPS com perguntas fixas sem árvore inteligente; ausência de tarifação adaptada por patologia; regra decidida sem comparativo de mercado sistemático. | G3: Taxa de recusa e de pendência por motivo; comparativo de critérios de aceitação vs. concorrentes; volume de propostas perdidas após pedido de exame; tempo médio de aceitação; 'número invisível' (cotações não feitas). | H3: F07: 'Avaliar a aceitação técnica em comparação ao mercado para evitar perdas de negócios por rigidez processual'. F10: 'Descolamento das regras da companhia frente ao mercado'. F18: 'O gargalo real mapeado foi a aceitação e as travas sistêmicas... o que faz o corretor orientar o mercado a nem calcular na Unimed'. F23: 'Fricção e morosidade no processo de aceitação do Vida... migração de corretores para concorrentes'. | I3: F07; F10; F18; F23 | J3: =LEN(I3)-LEN(SUBSTITUTE(I3,"F","")) -> 4 | K3: 04/05/2026 | L3: 17/08/2026 | M3: Vida | N3: Direta | O3: =J3+(1000-ROW())/100000 -> 4.00997
A4: OT-03 | B4: Organização do Trabalho | C4: Papéis | D4: Responsabilidades pouco claras entre áreas; Estratégia Comercial vira destino de assuntos avulsos | E4: Demandas chegam sem filtro à Estratégia Comercial. Outras áreas desconhecem produtos e responsabilidades da SUSEP. O grupo debate se a solução é RH (cargos e capacity) ou planos diretivos, e conclui que é mudança cultural. | F4: Matriz de responsabilidades inexistente ou não difundida; SUSEP tratada como tema periférico dentro de uma companhia centrada em Saúde; ausência de porta de entrada única para demandas. | G4: Existência e uso de matriz RACI por processo; % de demandas recebidas pela Estratégia Comercial fora do seu escopo; tempo gasto em 'assuntos avulsos'; nº de áreas que conhecem o portfólio SUSEP (pesquisa interna). | H4: F21: 'Necessidade de clareza sobre as responsabilidades de cada área para evitar que a estratégia comercial seja sempre a responsável de assuntos avulsos'; 'É crucial evitar o direcionamento de demandas sem filtro para a área de Estratégia Comercial'; Glace: 'há um desconhecimento geral sobre produtos e responsabilidades'. | I4: F21 | J4: =LEN(I4)-LEN(SUBSTITUTE(I4,"F","")) -> 1 | K4: 03/08/2026 | L4: 03/08/2026 | M4: Vida e RE | N4: Direta | O4: =J4+(1000-ROW())/100000 -> 1.00996
A5: OT-04 | B5: Organização do Trabalho | C5: Carga de trabalho | D5: Operação saturada: sem capacidade para novos OKRs ou projetos | E5: A operação (subscrição e operação, segundo a ata) declara que já está sobrecarregada para sustentar as entregas correntes. O grupo decide formalmente não assumir novos OKRs impulsionadores nem cadastrar novas iniciativas, e passa a defender isso nos fóruns executivos. | F5: Ausência de equipe dedicada a projetos ou inovação (só Produtos tem subárea de projetos); rotina operacional consome o mesmo braço que executaria a estratégia; meta de crescimento de 20% pressiona por novas frentes sem alocação de pessoal. | G5: Horas de rotina vs. horas em iniciativas por pessoa; nº de iniciativas ativas por responsável; nº de OKRs recusados por falta de braço; backlog de melhorias operacionais paradas; nota de 'processos' na pesquisa de clima. | H5: F20: 'a operação atual já está bastante sobrecarregada... não havendo capacidade técnica para a criação de novos OKRs'. F22: 'dificuldade de assumir novos projetos devido à alta carga de rotina... inexistência de equipe exclusiva para inovação'; 'ações profundas de retenção dependem de capacity das áreas'. | I5: F20; F22 | J5: =LEN(I5)-LEN(SUBSTITUTE(I5,"F","")) -> 2 | K5: 11/08/2026 | L5: 17/08/2026 | M5: Vida e RE | N5: Direta | O5: =J5+(1000-ROW())/100000 -> 2.00995
A6: OT-05 | B6: Organização do Trabalho | C6: Carga de trabalho | D6: Desfalque de consultores estratégicos sobrecarrega a liderança do GT | E6: Três consultores (Aline, Márcio, Cibele) saem do time de estratégia comercial em RE e Vida. A líder Jacqueline absorve o dia a dia operacional e a implantação do novo modelo de Placement, além de acompanhar a esteira da Corretora Digital. Como alívio, a condução das reuniões semanais passa a ser rotativa com o colíder Alan. | F6: Reposição de pessoal lenta; liderança técnica acumula papel de executora; estrutura enxuta sem redundância de competências; frentes de canais dependem do mesmo time reduzido. | G6: Headcount previsto vs. real na estratégia comercial; tempo médio de reposição; % da agenda da líder em tarefas operacionais; nº de entregas atrasadas atribuídas a falta de braço. | H6: F14: 'Déficit severo de braços técnicos (desfalque de três consultores estratégicos em RE e Vida), sobrecarregando a liderança'. F16: 'Desfalque no time de consultores (saídas de Aline, Márcio e Cibele), gerando sobrecarga'. F18: 'time de estratégia comercial com time reduzido'. | I6: F14; F16; F18 | J6: =LEN(I6)-LEN(SUBSTITUTE(I6,"F","")) -> 3 | K6: 11/06/2026 | L6: 13/07/2026 | M6: Vida e RE (estratégia comercial) | N6: Direta | O6: =J6+(1000-ROW())/100000 -> 3.00994
A7: OT-06 | B7: Organização do Trabalho | C7: Autonomia | D7: Corretor sem autonomia na renovação: ferramenta sobe só o as-is e força emissão como seguro novo | E7: Na renovação do residencial o corretor não consegue alterar coberturas ou LMG e emite uma nova apólice, o que aparece como evasão no indicador de renovação e migra renovações para a esteira de 'venda nova'. | F7: Ferramenta especificada por Produtos sem alinhamento com Operação/Subscrição; esteira de renovação tratada como réplica e não como negociação; indicadores desenhados sem considerar o comportamento induzido pela ferramenta. | G7: Taxa de renovação real vs. registrada; nº de apólices 'novas' com CPF e risco idênticos a apólice vencida; % de renovações com alteração de cobertura; retenção após entrega do Calcule+ mês 09. | H7: F22: 'a ferramenta atual subiu apenas o as-is, impedindo o corretor de alterar coberturas/LMG e forçando-o a emitir uma nova apólice'; 'falha funcional na ferramenta de renovação do residencial criada por Produtos'. | I7: F22 | J7: =LEN(I7)-LEN(SUBSTITUTE(I7,"F","")) -> 1 | K7: 17/08/2026 | L7: 17/08/2026 | M7: RE (Residencial) | N7: Direta | O7: =J7+(1000-ROW())/100000 -> 1.00993
A8: OT-07 | B8: Organização do Trabalho | C8: Direitos decisórios | D8: Compliance e subscrição decidem por análise subjetiva: falso positivo recusa proposta de R$ 1 milhão | E8: Cliente da Unicred tem proposta de Vida recusada e enviada ao Compliance por suspeita de lavagem devido a pequena divergência de renda declarada. Gerentes das cooperativas preferem migrar para concorrentes com aceitação automática. | F8: Direito de decidir a aceitação distribuído entre subscrição, medicina e compliance sem regra clara de alçada por capital segurado; falta de aculturamento interno sobre o produto; atrito burocrático em capitais menores. | G8: Nº de propostas enviadas a compliance por faixa de capital e desfecho; tempo de decisão; existência de alçadas por valor; % de falsos positivos; perda de engajamento medida junto aos gerentes das cooperativas. | H8: F11: 'proposta de R$ 1 milhão (Vida) foi recusada e encaminhada ao Compliance sob suspeita de lavagem de dinheiro devido a uma pequena divergência de renda'; 'excesso de atrito burocrático e o risco iminente de perder o engajamento dos gerentes de contas das cooperativas'; 'mitigando análises subjetivas excessivas em capitais segurados menores'. | I8: F11 | J8: =LEN(I8)-LEN(SUBSTITUTE(I8,"F","")) -> 1 | K8: 18/05/2026 | L8: 18/05/2026 | M8: Vida (canal Cooperativas) | N8: Direta | O8: =J8+(1000-ROW())/100000 -> 1.00992
A9: OT-08 | B9: Organização do Trabalho | C9: Conhecimento local | D9: Conhecimento dos escritórios regionais e gerentes pouco capturado na análise de evasão de corretores | E9: Pesquisa com escritórios sobre motivos de saída de corretores fica 'aguardando retornos' e não finalizada em agosto. Relatório 'lupa' regionalizado pelos 9 gerentes é prometido em julho. Percepção da ponta sobre recusas diverge dos números operacionais. | F9: Análise conduzida centralmente pela estratégia; gerentes regionais consultados por pesquisa assíncrona; ausência de rito regular de escuta da ponta; dados de origem (ponto de venda) não rastreáveis. | G9: Taxa de resposta dos escritórios; existência do relatório regional; nº de decisões comerciais que citam insumo da ponta; convergência entre percepção da ponta e indicadores (reunião de alinhamento de recusas). | H9: F24: 'Pesquisa com os escritórios sobre os motivos de saída (churn) de corretores (aguardando retornos)'. F21: 'Pesquisa sobre corretores ainda não foi finalizada'. F18: 'A estratégia vai entregar nesta semana um relatório com lupa regionalizada (pelos 9 gerentes)'. F23: 'Esclarecer os dados reais de recusas na reunião com os gerentes comerciais... para alinhar a percepção do time de ponta com os números operacionais'. | I9: F18; F21; F23; F24 | J9: =LEN(I9)-LEN(SUBSTITUTE(I9,"F","")) -> 4 | K9: 13/07/2026 | L9: 17/08/2026 | M9: Vida e RE (canal Corretor) | N9: Inferida | O9: =J9+(1000-ROW())/100000 -> 4.00991
A10: OT-09 | B10: Organização do Trabalho | C10: Interdependência | D10: Frentes de negócio dependem da fila da TI e da área de Projetos para qualquer automação | E10: Motores de cálculo só funcionam com front-end; front-ends e motores não são desenvolvidos em sincronia (ociosidade). Hub de Cooperativas depende de Rafael/Projetos para levantamentos. Melhorias em cotadores, APIs e renovação aguardam a esteira de TI. | F10: TI centralizada com capacidade limitada atendendo Saúde, Odonto e SUSEP; sem squads dedicadas por negócio até jun/26; planejamento atuarial reativo a 'pedidos avulsos'. | G10: Lead time de demandas SUSEP na fila de TI; nº de entregas bloqueadas por dependência externa; % do backlog SUSEP com desenvolvedor alocado; existência de squad dedicada. | H10: F05: 'dependência da TI (equipe da Alessandra) para automação'; 'alinhar a implementação de front-ends com o desenvolvimento de motores de cálculo para evitar ociosidade'. F15: Landi 'está na dependência de Rafael e equipe de projetos para levantamentos'. F22: 'gargalos constantes na fila de priorização de TI'. F09: tarefa recorrente da TI de 'varredura de melhorias pendentes nos cotadores para evitar descontentamento de corretores'. | I10: F05; F09; F15; F22 | J10: =LEN(I10)-LEN(SUBSTITUTE(I10,"F","")) -> 4 | K10: 09/04/2026 | L10: 17/08/2026 | M10: Vida e RE | N10: Direta | O10: =J10+(1000-ROW())/100000 -> 4.0099
A11: OT-10 | B11: Organização do Trabalho | C11: Interdependência | D11: Marketing, Comercial e Produtos não andam juntos: patrocínio do SPFC sem plano de negócio integrado | E11: Contrato de R$ 45 milhões (até 2028) sem plano imediato para converter exposição em vendas. Marketing cobra condições comerciais da corretora digital e avança tratativas com o clube sem aval técnico da Estratégia. Desenvolvimento de novo produto demora cerca de dois anos. | F11: Decisão de patrocínio tomada fora do circuito comercial/produtos; contrapartidas não comunicadas às áreas; ausência de rito de ativação comercial de marca; ciclo de produto lento. | G11: Existência de plano de negócios do patrocínio com metas de venda; nº de tratativas comerciais com o clube que passaram por validação técnica; prazo médio de desenvolvimento de produto; receita atribuída à ativação. | H11: F12: 'Questionou-se a falta de um plano de negócios integrado e imediato para converter a exposição de marca em vendas... as áreas não andam juntas e que o desenvolvimento de novos produtos costuma demorar cerca de dois anos'. F15: 'tratativas comerciais avançadas... estão ocorrendo diretamente com o São Paulo FC, omitindo o aval técnico da estratégia'. F13: 'o Marketing cobrou o envio para a corretora digital por condições comerciais e descontos sem um alinhamento prévio estratégico'. F16: 'o Marketing solicitou a definição de uma condição diferenciada (desconto) para a loja do Sócio Torcedor'. | I11: F12; F13; F15; F16 | J11: =LEN(I11)-LEN(SUBSTITUTE(I11,"F","")) -> 4 | K11: 01/06/2026 | L11: 22/06/2026 | M11: Vida e RE (Marketing) | N11: Direta | O11: =J11+(1000-ROW())/100000 -> 4.00989
A12: OT-11 | B12: Organização do Trabalho | C12: Divisão do trabalho | D12: Vida e RE misturados no mesmo grupo, relatório e metas, gerando confusão estratégica | E12: Mentor pede desde março a separação das pautas, dos fluxos de acompanhamento e das metas por ramo e produto. Em junho a segregação ainda é 'prometida há meses' e o grupo teme cobrança da diretoria por dados agregados. A reestruturação do Estratos em duas esteiras só é desenhada em junho. | F12: Dinâmicas de distribuição e perfis de cliente muito distintos entre Vida e RE; um único GT e um único relatório para dois negócios; meta global de 20% não desmembrada; ferramenta de gestão organizada por iniciativa e não por ramo/canal. | G12: Existência de metas, indicadores e relatórios abertos por ramo e por produto; tempo entre a diretriz do mentor e a implementação; nº de reuniões com pauta segregada (30 min por tema). | H12: F01 (slide 9): mentor Aguiar 'Recomendou separar claramente as reuniões e os fluxos de acompanhamento dos ramos Vida e RE... evitar confusão estratégica'. F13: 'Urgência na separação dos ramos Vida e RE dentro do status e do relatório (Stratws)... evitando penalizações da diretoria por dados agregados'; 'a divisão já vem sendo prometida há meses'. F14: nova árvore Vida x RE. Contraponto F02: a mistura 'gera transbordo de ideias positivas'. F03: 'Rodrigo Aguiar propôs a separação clara das pautas de Vida e Ramos Elementares nas reuniões'. F09: tarefa 'Abertura das metas por ramo', prazo agosto/2026. F17: 'O extrato de acompanhamento atual (Estratos) será encerrado para a abertura de um novo modelo que reflita... ações divididos por canais e segmentos (Vida e RE)'. | I12: F01; F02; F03; F09; F13; F14; F17 | J12: =LEN(I12)-LEN(SUBSTITUTE(I12,"F","")) -> 7 | K12: 30/03/2026 | L12: 29/06/2026 | M12: Vida e RE | N12: Direta | O12: =J12+(1000-ROW())/100000 -> 7.00988
A13: OT-12 | B13: Organização do Trabalho | C13: Divisão do trabalho | D13: Canal Unimed pulverizado entre áreas, sem coordenação, com sobreposição de contatos nas mesmas Unimeds | E13: Ações no canal Unimed espalhadas entre squads e áreas, gerando conflitos de atuação. Operação (Aretha) e Canais (Landi) precisam alinhar para não sobrepor contatos. Mentor determina nova diretriz sob liderança de Landi. Unimeds começam a criar corretoras cativas. | F13: Canal 'de casa' tratado como responsabilidade de todos e de ninguém; ausência de guarda-chuva comercial estruturado; companhia se diz 'seguradora do sistema' sem dados tratados para agir. | G13: Nº de áreas que abordam a mesma Unimed em um trimestre; existência de dono único do canal; plano de ataque segmentado por Unimed entregue; produção do canal vs. meta. | H13: F17: 'Sobre o Canal Unimed, há uma pulverização de ações entre áreas e falta de coordenação... o que gera conflitos de atuação entre squads'. F02: 'Aretha e Landi devem alinhar os assuntos para evitar sobreposição de contatos nas mesmas Unimeds'. F07: 'Necessidade de uma estratégia nacional coordenada'. F22: 'urgência de criar um guarda-chuva comercial estruturado'. | I13: F02; F07; F17; F22 | J13: =LEN(I13)-LEN(SUBSTITUTE(I13,"F","")) -> 4 | K13: 30/03/2026 | L13: 17/08/2026 | M13: Vida e RE (canal Unimed) | N13: Direta | O13: =J13+(1000-ROW())/100000 -> 4.00987
... A73: TE-11 | B73: Tecnologia | C73: Automação | D73: Motores de cálculo incompletos: endosso e renovação analógicos; prestamista o mais manual | E73: Painel verde/amarelo/vermelho mostra grande volume de produtos sem motor automatizado. Mapeamento 'o que tem vs. o que falta' pedido em maio. Prestamista levaria ~3 anos para automatizar. | F73: Automação priorizada para venda nova e não para ciclo de vida da apólice; motores Drools dependem de front-end; sem roadmap único. | G73: % de produtos com motor em endosso e renovação; volume de operações manuais por mês; prazo de entrega do mapeamento de motores. | H73: F05: 'há um grande volume de produtos (especialmente em endosso e renovação) que ainda operam de forma analógica/técnica, sem motor automatizado'; 'a companhia não tem 100% dos motores estruturados'. F11: prestamista 'o produto mais analógico da companhia'. F09: tarefa 'Enviar mapeamento atualizado de motores de cálculo e cotadores (o que tem vs. o que falta)'. | I73: F05; F09; F11 | J73: =LEN(I73)-LEN(SUBSTITUTE(I73,"F","")) -> 3 | K73: 09/04/2026 | L73: 18/05/2026 | M73: Vida e RE | N73: Direta | O73: =J73+(1000-ROW())/100000 -> 3.00927

Sheet Taxonomia
A1: Categoria | B1: Elemento | C1: Nº de sintomas | D1: Cobertura
A2: Organização do Trabalho | B2: Padrões | C2: =COUNTIFS(Sintomas!$B$2:$B$73,A2,Sintomas!$C$2:$C$73,B2,Sintomas!$N$2:$N$73,"<>Sem evidência") -> 2 | D2: =IF(C2=0,"Sem evidência nas fontes",IF(C2=1,"1 sintoma",C2&" sintomas")) -> 2 sintomas
A3: Organização do Trabalho | B3: Papéis | C3: =COUNTIFS(Sintomas!$B$2:$B$73,A3,Sintomas!$C$2:$C$73,B3,Sintomas!$N$2:$N$73,"<>Sem evidência") -> 1 | D3: =IF(C3=0,"Sem evidência nas fontes",IF(C3=1,"1 sintoma",C3&" sintomas")) -> 1 sintoma
A4: Organização do Trabalho | B4: Carga de trabalho | C4: =COUNTIFS(Sintomas!$B$2:$B$73,A4,Sintomas!$C$2:$C$73,B4,Sintomas!$N$2:$N$73,"<>Sem evidência") -> 2 | D4: =IF(C4=0,"Sem evidência nas fontes",IF(C4=1,"1 sintoma",C4&" sintomas")) -> 2 sintomas
A5: Organização do Trabalho | B5: Autonomia | C5: =COUNTIFS(Sintomas!$B$2:$B$73,A5,Sintomas!$C$2:$C$73,B5,Sintomas!$N$2:$N$73,"<>Sem evidência") -> 1 | D5: =IF(C5=0,"Sem evidência nas fontes",IF(C5=1,"1 sintoma",C5&" sintomas")) -> 1 sintoma
A6: Organização do Trabalho | B6: Direitos decisórios | C6: =COUNTIFS(Sintomas!$B$2:$B$73,A6,Sintomas!$C$2:$C$73,B6,Sintomas!$N$2:$N$73,"<>Sem evidência") -> 1 | D6: =IF(C6=0,"Sem evidência nas fontes",IF(C6=1,"1 sintoma",C6&" sintomas")) -> 1 sintoma
A7: Organização do Trabalho | B7: Conhecimento local | C7: =COUNTIFS(Sintomas!$B$2:$B$73,A7,Sintomas!$C$2:$C$73,B7,Sintomas!$N$2:$N$73,"<>Sem evidência") -> 1 | D7: =IF(C7=0,"Sem evidência nas fontes",IF(C7=1,"1 sintoma",C7&" sintomas")) -> 1 sintoma
A8: Organização do Trabalho | B8: Interdependência | C8: =COUNTIFS(Sintomas!$B$2:$B$73,A8,Sintomas!$C$2:$C$73,B8,Sintomas!$N$2:$N$73,"<>Sem evidência") -> 2 | D8: =IF(C8=0,"Sem evidência nas fontes",IF(C8=1,"1 sintoma",C8&" sintomas")) -> 2 sintomas
A9: Organização do Trabalho | B9: Divisão do trabalho | C9: =COUNTIFS(Sintomas!$B$2:$B$73,A9,Sintomas!$C$2:$C$73,B9,Sintomas!$N$2:$N$73,"<>Sem evidência") -> 2 | D9: =IF(C9=0,"Sem evidência nas fontes",IF(C9=1,"1 sintoma",C9&" sintomas")) -> 2 sintomas
A10: Organização do Trabalho | B10: Especialização | C10: =COUNTIFS(Sintomas!$B$2:$B$73,A10,Sintomas!$C$2:$C$73,B10,Sintomas!$N$2:$N$73,"<>Sem evidência") -> 3 | D10: =IF(C10=0,"Sem evidência nas fontes",IF(C10=1,"1 sintoma",C10&" sintomas")) -> 3 sintomas
A11: Organização do Trabalho | B11: Accountability | C11: =COUNTIFS(Sintomas!$B$2:$B$73,A11,Sintomas!$C$2:$C$73,B11,Sintomas!$N$2:$N$73,"<>Sem evidência") -> 1 | D11: =IF(C11=0,"Sem evidência nas fontes",IF(C11=1,"1 sintoma",C11&" sintomas")) -> 1 sintoma
A12: Governança | B12: Delegação | C12: =COUNTIFS(Sintomas!$B$2:$B$73,A12,Sintomas!$C$2:$C$73,B12,Sintomas!$N$2:$N$73,"<>Sem evidência") -> 2 | D12: =IF(C12=0,"Sem evidência nas fontes",IF(C12=1,"1 sintoma",C12&" sintomas")) -> 2 sintomas
A13: Governança | B13: Transparência | C13: =COUNTIFS(Sintomas!$B$2:$B$73,A13,Sintomas!$C$2:$C$73,B13,Sintomas!$N$2:$N$73,"<>Sem evidência") -> 1 | D13: =IF(C13=0,"Sem evidência nas fontes",IF(C13=1,"1 sintoma",C13&" sintomas")) -> 1 sintoma
... A44: Tecnologia | B44: Automação | C44: =COUNTIFS(Sintomas!$B$2:$B$73,A44,Sintomas!$C$2:$C$73,B44,Sintomas!$N$2:$N$73,"<>Sem evidência") -> 1 | D44: =IF(C44=0,"Sem evidência nas fontes",IF(C44=1,"1 sintoma",C44&" sintomas")) -> 1 sintoma

Sheet Guia 1 Lente DO
A1: Guia 1. Lente de design organizacional: o que é disfuncional e o que precisa ser definido
A2: Leitura dos 72 sintomas por dimensão de design. Colunas amarelas são proposta e devem ser validadas com o time (criar com o time, para o time).
A3: Dimensão do design | B3: O que é disfuncional hoje | C3: Sintomas (IDs) | D3: O que precisa ser definido | E3: Pergunta de design para o time | F3: Quem deve decidir (proposta)
A4: 1. Direção e metas | B4: A meta de 20% não tem base rastreável, diverge do orçamento da Controladoria e não está aberta por ramo e produto. A frente carrega o gap do ano anterior e discute 'refluctuar' a meta em vez de reconciliar os dois sistemas de metas. | C4: GV-05; GV-01; OT-11; IN-10 | D4: Um número-base oficial (fechamento 2024) assinado por Controladoria e Estratégia; metas abertas por ramo (Vida, RE) e produto; regra de reconciliação entre A3 e orçamento; indicador técnico (sinistro) ao lado da meta de crescimento. | E4: Qual é o número que todos aceitam como ponto de partida, e quem tem o poder de mudá-lo? | F4: Diretoria Comercial (mentor Aguiar) com Controladoria; frente propõe, PIE homologa.
A5: 2. Estrutura, papéis e divisão do trabalho | B5: Um GT para dois negócios (Vida e RE) com dinâmicas distintas; canal Unimed pulverizado; Estratégia Comercial vira destino de assuntos avulsos; só Produtos tem subárea de projetos; conhecimento SUSEP concentrado no GT. | C5: OT-11; OT-12; OT-03; OT-15; OT-13; OT-14 | D5: Duas esteiras (Vida e RE) com líder, indicadores e relatório próprios; dono único do canal Unimed e do canal Cooperativas; matriz de responsabilidades (quem faz, quem decide, quem é consultado) para SUSEP; função de melhoria contínua nas áreas operacionais. | E5: Se Vida e RE são negócios diferentes, por que compartilham o mesmo desenho? O que ganha e o que perde ao separar? | F5: Líder do GT e facilitadora da Estratégia desenham; mentores validam; RH formaliza.
A6: 3. Direitos decisórios e alçadas | B6: Decisões de política comercial (esgotamento de comissão), de aceitação (compliance, DPS) e de escopo de TI sobem para mentores, COMEX ou RDS. A frente executa mas não decide. Não há via de recurso para recusas. | C6: GV-07; GV-02; OT-07; GV-04; GV-08; TE-09 | D6: Tabela de alçadas por tipo de decisão e valor (o que o GT decide sozinho, o que vai ao fórum, o que vai ao COMEX); alçadas de aceitação por capital segurado; rito de reconsideração de recusas; regra de consentimento técnico para ofertas lançadas por Marketing ou parceiros. | E6: Quais decisões o GT pode tomar hoje sem pedir permissão? Quais deveria poder? | F6: Diretoria define alçadas; GT propõe a lista a partir dos casos de 2026.
A7: 4. Fluxo de demanda e priorização | B7: Dores da SUSEP chegam por vários comitês (Frente, S&OP, Diagnóstico Comercial, RDS) e por planilhas coletivas que ninguém preenche; diagnóstico com centenas de itens sem filtro; comitê de priorização nasce como MVP e começa por Saúde; 'focar em tudo resulta em não entregar nada'. | C7: GV-06; CO-08; IN-01; OT-16; CO-01; CO-04 | D7: Porta de entrada única (ficha de demanda); time de triagem com cadência; tipologia (estrutural, BAU, adequação, oportunidade); critérios de relevância explícitos; fila única visível às esteiras executoras; regra de 'não abre frente sem braço'. | E7: Como um desafio entra, quem o vê primeiro, e como ele sai (resolvido, recusado ou estacionado)? | F7: Estratégia (VMO/Daniele) desenha o fluxo com o GT; comitê unificado SUSEP opera.
A8: 5. Capacidade e alocação (gente e tempo) | B8: Operação saturada; três consultores a menos; líder absorve o operacional; TI sem braço dedicado à SUSEP; dependência de pessoas-chave; agendas colidem com COMEX, cursos e férias; reunião semanal curta para temas técnicos. | C8: OT-04; OT-05; RE-08; RE-09; RE-04; RE-05; OT-09 | D8: Dedicação mínima por membro do GT (horas protegidas); squad com núcleo fixo para SUSEP (TI, Processos, Dados); suplente por frente crítica; calendário anual de ritos com prioridade formal; plano de reposição de consultores. | E8: Quanto tempo cada pessoa realmente tem para a frente, e o que sai da rotina para abrir espaço? | F8: Superintendentes (mentores) alocam; RH e Estratégia registram a dedicação.
A9: 6. Sistemas, dados e ferramentas | B9: Defasagem de 5 anos; motores incompletos; sem APIs; pagamentos só em 2027; BI fora do ar; ponto de venda não rastreável; vidas não contáveis; renovação as-is; portal sem pagamentos; ferramenta de gestão trocada duas vezes em seis meses. | C9: TE-07; TE-11; TE-08; TE-04; IN-12; IN-11; IN-07; OT-06; TE-03; GV-09; IN-06 | D9: Roadmap único produto-motor-front-API com fatia reservada à SUSEP; dono de produto digital para cotadores e portais; padrão mínimo de dados (cliente único, ponto de venda, vidas); critério de estabilidade para ferramenta de gestão (não trocar sem migrar histórico). | E9: Quais dez processos manuais, se automatizados, mudam o ponteiro? Quem decide a ordem? | F9: TI (Alessandra) com Produtos e Estratégia; comitê de priorização ordena; diretoria patrocina.
A10: 7. Ritos, cadência e memória | B10: Reuniões sem pauta; engajamento só na reunião; 80/20 de status; ritos com mentores de 30 minutos, adiados ou ausentes; fóruns preparados para evitar perguntas; memória só em atas (uma duplicada, marcas de geração automática). | C10: OT-01; OT-16; RE-05; GV-10; GV-03; IN-16 | D10: Padrão de pauta e resultado esperado; reunião semanal de deliberação (insumo antes); rito de triagem quinzenal; fórum mensal com deliberações registradas (dono, prazo); mentoria com no mínimo 1h por tema denso; repositório único de decisões. | E10: O que cada rito decide, e o que acontece se ele não acontecer? | F10: GT define e cumpre; Estratégia guarda o padrão; frente de Cultura apoia.
A11: 8. Interfaces externas (canais, parceiros, Marketing) | B11: Marketing e Corretora Digital decidem sem aval técnico; pós-venda PF sem dono; corretores somem após a primeira cotação; agências das cooperativas não sabem vender Vida; parceiros (Unicred) impõem prazos que a companhia não consegue cumprir. | C11: GV-08; CO-05; IN-05; OT-14; CO-03; RE-03; RE-02 | D11: Regra de consentimento para ofertas e canais novos; dono do pós-venda PF; programa nacional de onboarding de corretores; esteira sem fricção para cooperativas; acordo de nível de serviço com parceiros (prazos realistas). | E11: Quem representa a SUSEP na mesa quando Marketing, parceiro ou cooperativa decide algo que a operação terá de sustentar? | F11: Líder do GT como representante formal; mentor Aguiar arbitra com Marketing.
A12: 9. Medição de sucesso e aprendizado | B12: Percentuais de conclusão confundem entrega com resultado; 'não-ganhos' e 'número invisível' não são registrados; percepção da ponta e dados divergem; sinistralidade fora do painel; concorrência percebida tarde. | C12: GV-09; IN-04; IN-02; IN-10; IN-14; IN-09 | D12: Poucos indicadores por esteira (resultado, técnico, operacional); registro de negócios perdidos por causa; rito de leitura conjunta dado e ponta; radar de mercado com dono e periodicidade; definição de sucesso por iniciativa antes de começar. | E12: Como saberemos, em três meses, que o novo desenho funcionou? | F12: GT define os indicadores; Estratégia mede; mentores cobram.
A13: Números nas propostas (cotas, limites, horas, durações) são pontos de partida para calibrar com o time (Guia 6), não recomendações fechadas.

Sheet Guia 2 Fluxo demanda
A1: Guia 2. Como os desafios chegam, como eles saem, e como sei o que é relevante
A2: Bloco A: etapas do fluxo (hoje x proposto). Bloco B: critérios de relevância. Bloco C: modelo de pontuação para o time preencher (células azuis são entrada).
A3: Etapa | B3: Como acontece hoje (evidência) | C3: Sintomas (IDs) | D3: Como deveria acontecer (proposta) | E3: Regra | F3: Dono (proposta) | G3: Artefato
A4: 1. Entrada | B4: Demandas chegam por reunião, WhatsApp, e-mail, planilhas coletivas, S&OP, RDS, Marketing e parceiros; a Estratégia Comercial recebe 'assuntos avulsos' sem filtro. | C4: CO-08; OT-03; GV-08 | D4: Porta única: ficha de demanda com problema, quem sofre, evidência, valor esperado e prazo externo (se houver). Sem ficha, não entra na fila. | E4: Toda demanda tem ficha e autor. | F4: Facilitadora da Estratégia (Fabíola) | G4: Ficha de demanda (1 página)
A5: 2. Registro e visibilidade | B5: Planilhas apartadas, lembretes repetidos, histórico zerado a cada troca de ferramenta. | C5: OT-16; GV-09; IN-16 | D5: Fila única visível (Jira) com status, tipo, dono e decisão. Histórico preservado. | E5: Uma fila, uma ferramenta, um histórico. | F5: Estratégia (PMO da frente) | G5: Fila única no Jira
A6: 3. Triagem | B6: Não existe rito; tudo vai para a reunião semanal ou para o mentor. | C6: GV-06; GV-02; RE-05 | D6: Time de triagem quinzenal (30 min) classifica em: Estrutural, BAU, Adequação ou Oportunidade; aplica critérios de relevância; devolve demandas mal enquadradas ao autor. | E6: Nenhuma demanda vai a fórum sem passar pela triagem. | F6: Time de triagem (ver Guia 3) | G6: Ficha carimbada com tipo e nota
A7: 4. Enquadramento | B7: Discussões repetitivas; listas com centenas de itens; mistura de receita, eficiência e lei. | C7: IN-01; GV-06 | D7: Para demandas relevantes: enquadrar o problema (causa raiz), a hipótese de solução, o valor em R$ ou tempo, e o que 'muda o ponteiro'. Máximo de 5 enquadramentos abertos por esteira. | E7: Enquadramento antes de estudo; limite de itens abertos. | F7: Líder da esteira (Vida ou RE) com Produtos | G7: Canvas de enquadramento (A3 curto)
A8: 5. Estudo | B8: Estudos surgem por provocação (Hub, Espaço Corretor, DPS) e dependem de uma pessoa e de dados que não existem. | C8: RE-09; IN-06; IN-14 | D8: Escolher o modo: Assessment fechado (pergunta definida, prazo curto), Discovery aberto (problema difuso, pesquisa com ponta e mercado), Olhar mercado (benchmark IM) ou Decupagem com TI (quebra de escopo em épicos com estimativa). Definir prazo e saída antes de começar. | E8: Todo estudo tem pergunta, modo, prazo e saída definidos. | F8: Dono do enquadramento; IM e TI como apoio | G8: Plano de estudo (meia página)
A9: 6. Concepção da solução | B9: Solução tende a ser 'pedir para a TI'; paliativos surgem sem registro (links no pós-venda). | C9: CO-10; OT-09; TE-05 | D9: Gerar opções: construir, comprar pronto, parceiro/terceiro, paliativo com retaguarda humana, ou não fazer. Comparar por valor, prazo, custo e risco. Registrar a opção escolhida e o porquê. | E9: Sempre pelo menos duas opções, uma delas 'não fazer'. | F9: Líder da esteira com TI, Produtos e Atuarial ('triângulo') | G9: Comparativo de opções
A10: 7. Decisão e priorização | B10: Priorização difusa; comitê como MVP; escalações frequentes; decisões travadas por anos (esgotamento de comissão). | C10: GV-06; GV-07; GV-02; CO-01 | D10: Comitê unificado SUSEP mensal decide dentro da alçada; acima dela, leva ao fórum com recomendação única. Cada decisão sai com dono, prazo, capacidade alocada e indicador de sucesso. | E10: Decisão sem dono, prazo e braço não é decisão. | F10: Comitê unificado SUSEP; fórum de gestão para exceções | G10: Ata de decisão (dono, prazo, braço, métrica)
A11: 8. Execução | B11: Projetos trocados por emergências; sem squad dedicada; dependência de fila da TI. | C11: CO-01; RE-08; OT-04 | D11: Executar em squad com núcleo fixo (TI, Processos, Dados) e participantes volantes; para temas críticos, 'sala de guerra' (poucas pautas, conclusão em semanas). Emergências operacionais em fila separada com cota. | E11: Emergência não rouba a fila de projeto sem decisão do comitê. | F11: Líder da squad; TI (Alessandra) | G11: Quadro da squad; cota de emergência
A12: 9. Entrega e adoção | B12: Ferramentas entram incompletas (portal sem pagamentos, renovação as-is); comunicação à ponta filtrada. | C12: TE-03; OT-06; IN-03; IN-15 | D12: Definição de pronto inclui: jornada ponta a ponta, comunicação ao comercial, FAQ/matriz de coberturas atualizada, e validação com a operação que vai sustentar. | E12: Nada entra em produção sem a operação e a ponta terem visto. | F12: Produtos e Operação em conjunto | G12: Checklist de pronto
A13: 10. Medição | B13: % de conclusão confunde entrega e resultado; não-ganhos não registrados. | C13: GV-09; IN-04; IN-02 | D13: Cada entrega tem indicador de resultado (venda, retenção, tempo, custo) medido 30 e 90 dias depois; negócios perdidos por limitação registrados na mesma fila. | E13: Entrega sem medição não fecha. | F13: Estratégia mede; dono responde | G13: Painel por esteira
A14: 11. Saída (encerramento) | B14: Itens somem, ficam em 'estacionamento de ideias' ou são fechados administrativamente para limpar histórico. | C14: GV-09; GV-06 | D14: Três saídas explícitas: Resolvido (com resultado medido), Recusado (com motivo registrado) ou Estacionado (com data de revisão). Toda demanda sai por uma delas. | E14: Nenhuma demanda desaparece. | F14: Comitê unificado | G14: Registro de encerramento
A16: Bloco B. Como sei o que é relevante: critérios de relevância
A17: Critérios extraídos das próprias fontes (quem propôs e onde) e organizados como filtro de triagem.
A18: Critério | B18: Pergunta de triagem | C18: Origem nas fontes | D18: Peso sugerido (0 a 5)
A19: Muda o ponteiro de crescimento | B19: A demanda altera venda nova, renovação ou retenção de forma mensurável em Vida ou RE? | C19: F13: 'focar as listas de diagnóstico em itens que de fato alterem o ponteiro de crescimento'; F11: 'o que traz resultado de imediato para virar os ponteiros' | D19: 5
A20: Tipo: receita, eficiência ou lei | B20: É geração de receita, eficiência operacional básica ou exigência regulatória? (lei tem prazo e não se discute; eficiência básica vai para BAU) | C20: F13: filtros de Tatiane separando receita, eficiência e regulatório | D20: 4
A21: Prontidão | B21: Está pronto para escala imediata ou exige construir do zero? (Vida Individual pronto x Prestamista analógico) | C21: F11: 'focar no que está pronto para escala imediata e criar alternativa viável para o resto' | D21: 4
A22: Impacto x esforço | B22: Qual o valor estimado (R$, tempo, clientes) contra o esforço e a dependência de TI? | C22: F13: 'filtros de impacto vs. esforço complexidade' | D22: 4
A23: Prazo externo | B23: Há prazo imposto por parceiro, regulador ou mercado? (Unicred jan/2027; Nova Lei; BC Pix) | C23: F17: prestamista 'prazo para janeiro de 2027 é altamente crítico'; F02: movimento do Banco Central | D23: 3
A24: Canal e volume | B24: Atinge o canal corretor (65% da operação), cooperativas em crescimento ou o canal Unimed? | C24: F22: 'o canal corretor representa 65% da operação da SUSEP' | D24: 3
A25: Custo do não-ganho | B25: Quanto já se perdeu por não ter isso? (esgotamento de comissão, DPS, pagamentos) | C25: F12: documentar 'não-ganhos'; F18: 'número invisível' | D25: 3
A26: Braço disponível | B26: Existe capacidade real (pessoas e TI) para executar sem tirar de entrega em curso? | C26: F20 e F22: não assumir novas frentes sem braço | D26: 5
A27: Peso é proposta: o time calibra na sessão de co-criação (Guia 6).
A28: Bloco C. Modelo de pontuação (template para o time preencher)
A29: Entradas em azul (0 a 5 por critério). A nota é fórmula: soma ponderada pelos pesos do Bloco B. Linhas de exemplo são ilustrativas e devem ser revistas pelo time.
A30: Pesos | B30: =$D$19 -> 5 | C30: =$D$20 -> 4 | D30: =$D$21 -> 4 | E30: =$D$22 -> 4 | F30: =$D$23 -> 3 | G30: =$D$24 -> 3 | H30: =$D$25 -> 3 | I30: =$D$26 -> 5 | J30: Nota máxima | K30: =5*SUM(B30:I30) -> 155
A31: Demanda (exemplo) | B31: Muda o ponteiro | C31: Tipo (lei=5, receita=4, eficiência=2) | D31: Prontidão | E31: Impacto x esforço | F31: Prazo externo | G31: Canal e volume | H31: Custo do não-ganho | I31: Braço disponível | J31: Nota (fórmula) | K31: % da máxima | L31: Tipo (triagem)
A32: Esgotamento de comissão em RE (GV-07) | B32: 5 | C32: 4 | D32: 3 | E32: 4 | F32: 2 | G32: 5 | H32: 5 | I32: 3 | J32: =SUMPRODUCT(B32:I32,$B$30:$I$30) -> 120 | K32: =IF($K$30=0,0,J32/$K$30) -> 0.77419355 | L32: Estrutural
A33: Prestamista prêmio único Unicred (CO-03) | B33: 4 | C33: 4 | D33: 1 | E33: 3 | F33: 5 | G33: 4 | H33: 4 | I33: 1 | J33: =SUMPRODUCT(B33:I33,$B$30:$I$30) -> 96 | K33: =IF($K$30=0,0,J33/$K$30) -> 0.61935484 | L33: Estrutural
A34: DPS inteligente / aceitação automática (TE-06) | B34: 4 | C34: 4 | D34: 2 | E34: 4 | F34: 2 | G34: 5 | H34: 4 | I34: 2 | J34: =SUMPRODUCT(B34:I34,$B$30:$I$30) -> 103 | K34: =IF($K$30=0,0,J34/$K$30) -> 0.66451613 | L34: Estrutural
A35: Restabelecer BI (IN-12) | B35: 2 | C35: 2 | D35: 5 | E35: 5 | F35: 1 | G35: 3 | H35: 2 | I35: 3 | J35: =SUMPRODUCT(B35:I35,$B$30:$I$30) -> 91 | K35: =IF($K$30=0,0,J35/$K$30) -> 0.58709677 | L35: BAU
A36: Cartas da Nova Lei de Seguros (F10) | B36: 1 | C36: 5 | D36: 4 | E36: 3 | F36: 5 | G36: 2 | H36: 1 | I36: 4 | J36: =SUMPRODUCT(B36:I36,$B$30:$I$30) -> 97 | K36: =IF($K$30=0,0,J36/$K$30) -> 0.62580645 | L36: Adequação
A37: Ativação comercial SPFC (OT-10) | B37: 3 | C37: 4 | D37: 4 | E37: 3 | F37: 3 | G37: 2 | H37: 2 | I37: 2 | J37: =SUMPRODUCT(B37:I37,$B$30:$I$30) -> 90 | K37: =IF($K$30=0,0,J37/$K$30) -> 0.58064516 | L37: Oportunidade
A38: (nova demanda) | B38: 0 | C38: 0 | D38: 0 | E38: 0 | F38: 0 | G38: 0 | H38: 0 | I38: 0 | J38: =SUMPRODUCT(B38:I38,$B$30:$I$30) -> 0 | K38: =IF($K$30=0,0,J38/$K$30) -> 0
A39: (nova demanda) | B39: 0 | C39: 0 | D39: 0 | E39: 0 | F39: 0 | G39: 0 | H39: 0 | I39: 0 | J39: =SUMPRODUCT(B39:I39,$B$30:$I$30) -> 0 | K39: =IF($K$30=0,0,J39/$K$30) -> 0
A40: (nova demanda) | B40: 0 | C40: 0 | D40: 0 | E40: 0 | F40: 0 | G40: 0 | H40: 0 | I40: 0 | J40: =SUMPRODUCT(B40:I40,$B$30:$I$30) -> 0 | K40: =IF($K$30=0,0,J40/$K$30) -> 0
A41: Legenda: azul = entrada do time; preto = fórmula. As notas dos exemplos são ilustrativas, não avaliação das fontes.

Sheet Guia 3 Triagem
A1: Guia 3. Triagem: tipos de problema, time de análise, o que estudar, o que terceirizar, como controlar e medir
A2: Tipologia proposta a partir dos casos registrados nas fontes. Colunas amarelas são proposta.
A3: Tipo de demanda | B3: Definição | C3: Como reconhecer | D3: Exemplos nas fontes (IDs) | E3: Quem analisa | F3: Caminho de estudo | G3: Terceirizar? (critério) | H3: Como controlar | I3: Como medir sucesso | J3: Regras
A4: Problema ESTRUTURAL (não atende) | B4: A companhia não consegue atender uma necessidade de mercado ou de parceiro porque falta capacidade sistêmica, processo ou política. Não se resolve com ajuste; exige construir, comprar ou mudar regra. | C4: Aparece repetidamente em atas por meses; concorrente já faz; parceiro exige; solução passa por TI, Atuarial e política ao mesmo tempo. | D4: GV-07 (esgotamento de comissão); CO-03 (prestamista prêmio único); TE-06 (DPS inteligente); TE-08 (APIs); TE-04 (pagamentos); CO-10 (cross-sell); TE-11 (motores); IN-07 (vidas por CPF) | E4: Time de triagem completo + dono de esteira + TI arquitetura | F4: Assessment fechado quando a pergunta é clara (ex.: quanto custa e quanto rende o esgotamento); Discovery aberto quando o problema é difuso (ex.: Hub de Cooperativas); sempre Olhar mercado (IM) e Decupar escopo com TI antes de decidir. | G4: Sim quando: mercado tem pronto (DPS via ressegurador Sample Med; APIs de mercado em POC), prazo externo é crítico (Unicred jan/2027) ou a capacidade interna é zero. Não quando: é core de precificação ou aceitação (fica com Atuarial e Subscrição). | H4: Comitê unificado mensal; épicos no Jira; gate por etapa (enquadrado, estudado, decidido, em execução); patrocinador nomeado (mentor). | I4: Resultado de negócio 90 dias após entrega (venda nova, retenção, tempo de aceitação); não-ganhos evitados; prazo externo cumprido. | J4: Não entra em execução sem patrocinador, braço alocado e indicador; máximo de 3 estruturais em execução por esteira.
A5: Problema de BAU (sustentação) | B5: Rotina que quebrou ou degrada o dia a dia: sistema fora do ar, dado errado, fila parada, retrabalho. Não muda o modelo de negócio, mas sem ele nada anda. | C5: Impacta hoje; tem solução conhecida; reclamação da ponta ou da operação; não precisa de estudo. | D5: IN-12 (BI fora do ar); CO-07 (remissão de faturas); IN-11 (códigos de corretor); CO-02 (pendências >40 dias); OT-06 (renovação as-is); TE-02 (erro na tela de pagamento) | E5: Operação/Subscrição (Alan, Aretha) + TI sustentação; não passa pela reunião do GT | F5: Sem estudo: correção direta com prazo. Se a mesma falha volta três vezes, vira Estrutural. | G5: Raramente; só suporte especializado pontual (fornecedor do sistema). | H5: Fila de sustentação separada da fila de projeto, com cota de capacidade da TI (ex.: 20%) e SLA por severidade. | I5: Tempo de restabelecimento; recorrência; horas manuais evitadas; nota de processos no clima. | J5: Emergência não entra na fila de projeto; BAU tem cota e SLA; reincidência escala.
A6: ADEQUAÇÃO (regulatório, parceiro, contrato) | B6: Exigência externa com prazo e sem opção de não fazer: lei, regulador (SUSEP, BC), contrato de parceiro, ressegurador. | C6: Tem data; tem penalidade; a discussão é 'como', não 'se'. | D6: Nova Lei de Seguros e cartas (F10); regra do BC para boletos (TE-04); saneamento SUSEP de corretores (IN-09); exigências documentais do ressegurador (CO-02); Unicred prêmio único (CO-03, também estrutural) | E6: Jurídico/Compliance + Produtos + dono de esteira; triagem só confirma prazo e escopo | F6: Assessment fechado (o que exatamente é exigido, até quando, o que falta). Decupar escopo com TI se houver sistema envolvido. | G6: Sim para expertise regulatória pontual; execução fica interna. | H6: Cronograma legal com marco no comitê; alerta 90/60/30 dias. | I6: Prazo cumprido; zero apontamento de auditoria; custo de adequação dentro do previsto. | J6: Adequação tem prioridade automática sobre Oportunidade, mas não suspende Estrutural em execução sem decisão do comitê.
A7: OPORTUNIDADE (opcional, com janela) | B7: Possibilidade de ganho que surge de fora (patrocínio, evento, parceiro novo, canal digital). Vale se for barata e rápida; não substitui o plano. | C7: Chega por Marketing, mentor ou parceiro; entusiasmo alto; escopo indefinido; sem dono operacional. | D7: OT-10 e RE-07 (SPFC); RE-03 (Espaço Corretor); Coopday e leads (F16); vendas no digital / TikTok (F09 estacionamento de ideias) | E7: Time de triagem + Marketing + IM | F7: Discovery aberto curto (2 a 4 semanas) com pergunta: 'o que já temos que pode ser empacotado?'. Olhar mercado obrigatório (benchmark). | G7: Sim para pesquisa e ativação (UX research, agência); produto e preço ficam internos. | H7: Piloto com prazo e orçamento fechados; revisão em 60 dias; encerramento explícito. | I7: Receita atribuída; custo por cliente; aprendizado registrado. | J7: Oportunidade só entra se não tirar braço de Estrutural em execução; sem plano de negócio não avança.
A9: Time de análise de demanda (proposta)
A10: Composição mínima, dedicação e papel. Criar com o time: nomes são os que aparecem nas fontes com o papel correspondente.
A11: Papel no time de triagem | B11: Quem hoje exerce papel próximo (fontes) | C11: Dedicação proposta | D11: O que faz na triagem | E11: O que não faz
A12: Facilitador e guardião do fluxo | B12: Fabíola (Estratégia) | C12: 4h por quinzena | D12: Convoca, garante ficha preenchida, registra decisão, mantém a fila única. | E12: Não decide mérito; não executa.
A13: Dono da esteira Vida | B13: Jacqueline (líder do GT) ou colíder | C13: 2h por quinzena | D13: Julga relevância para Vida; enquadra; leva ao comitê. | E13: Não absorve demandas avulsas de outras áreas.
A14: Dono da esteira RE | B14: Alan (colíder) | C14: 2h por quinzena | D14: Julga relevância para RE; representa Subscrição e Operação. | E14: Idem.
A15: Produtos | B15: Tatiane | C15: 2h por quinzena | D15: Confirma tipo (receita, eficiência, lei), prontidão e impacto em produto. | E15: Não assume desenvolvimento sem TI.
A16: Atuarial e técnica | B16: Glace | C16: 1h por quinzena | D16: Avalia efeito em preço, sinistro e apetite de risco. | E16: Não faz estudo de mercado.
A17: TI e arquitetura | B17: Alessandra | C17: 2h por quinzena | D17: Decupa escopo, estima esforço, diz o que é comprável e o que é construível. | E17: Não prioriza sozinha.
A18: Inteligência de mercado | B18: Daniel (IM) com equipe da IM | C18: 1h por quinzena | D18: Traz benchmark, radar e dados de concorrência para o critério 'olhar mercado'. | E18: Não decide.
A19: Canais | B19: Christian Landi | C19: 1h por quinzena (com suplente) | D19: Representa cooperativas e Unimeds; traz prazos e exigências de parceiros. | E19: Ausência não bloqueia: suplente decide.
A20: Processos e VMO | B20: Daniele (VMO) ou Cabral (Processos) | C20: 1h por quinzena | D20: Cruza com as esteiras executoras (TI, Processos, PMO, Inovação) e com o comitê de priorização. | E20: Não duplica a fila.
A21: Gente de fora (quando) | B21: Consultoria Linea (F12); Research/UX (Hugo, F19); ressegurador; Faculdade Unimed; birôs de dados | C21: Por estudo | D21: Discovery aberto, pesquisa com a ponta, benchmark, expertise regulatória ou tecnológica que não existe dentro. | E21: Não decide nem substitui o dono interno.
A23: Vamos estudar o quê? O que terceirizar? Como controlar? (matriz de decisão)
A24: Decisão | B24: Fazer internamente quando | C24: Terceirizar ou comprar quando | D24: Não fazer (ou paliativo) quando | E24: Controle mínimo | F24: Exemplo nas fontes
A25: Estudar (assessment fechado) | B25: A pergunta é clara e os dados existem em casa (Controladoria, Atuarial, RGS). | C25: A pergunta exige dado de mercado que não temos (cooperativas, concorrentes). | D25: A resposta não muda a decisão (estudar por estudar). | E25: Pergunta, prazo (máx. 4 semanas), responsável, saída escrita. | F25: Benchmark de esgotamento de comissão (F23); orçamento de sinistro por região (F24)
A26: Descobrir (discovery aberto) | B26: O problema é interno e a ponta está acessível (corretores, escritórios, gerentes). | C26: Precisa de método de pesquisa e neutralidade (UX research, consultoria). | D26: O tema já foi diagnosticado e só falta decidir. | E26: Hipóteses iniciais, amostra, prazo (máx. 8 semanas), síntese com recomendação. | F26: Espaço Corretor (F19); Hub de Cooperativas (F11); diagnóstico de churn (F09, F23)
A27: Olhar mercado | B27: Sempre, via IM, antes de qualquer estrutural. | C27: Quando IM não cobre o segmento (cooperativas, afinidades). | D27: Nunca pular. | E27: Radar com dono e periodicidade; fonte citada. | F27: Radar Estratégico e radar da IM (F15); painel V4 de sinistralidade (F06)
A28: Decupar escopo com TI | B28: Toda demanda estrutural antes de ir ao comitê. | C28: Arquitetura ou integração fora da competência atual (APIs, hub). | D28: Demanda BAU (vai direto para sustentação). | E28: Épicos, dependências, estimativa, o que é comprável; revisão com Produtos. | F28: POC de APIs (F16); mapeamento de motores (F05, F09); cross-sell como projeto (F06)
